# Live Position Handling Fixes - Quick Reference

## Summary

Fixed 3 bugs in live position handling:

### üî¥ HIGH: Generator Exception Not Caught
- **Bug**: Generator iteration not wrapped in try/except
- **Fix**: Added outer try/except around `for symbol, pnl, position in ...`
- **Impact**: Position monitor now resilient to API errors

### üü° MEDIUM: Limited Error Context
- **Bug**: Minimal context when errors occur
- **Fix**: Added exception type logging (`type(e).__name__`)
- **Impact**: Much easier to debug production issues

### üü¢ LOW: Insufficient Fallback Handling
- **Bug**: Fallback didn't check if `current_price` exists
- **Fix**: Added `'current_price' in locals()` check
- **Impact**: More robust error recovery

---

## Code Changes

### bot.py - Lines 288-326

```python
# BEFORE
def update_open_positions(self):
    for symbol, pnl, position in self.position_manager.update_positions():
        try:
            # ... record analytics ...
        except Exception as e:
            self.logger.error(...)

# AFTER
def update_open_positions(self):
    try:  # ‚Üê NEW: Outer try/except
        for symbol, pnl, position in self.position_manager.update_positions():
            try:
                # ... record analytics ...
            except Exception as e:
                self.logger.error(...)
    except Exception as e:  # ‚Üê NEW: Catch generator exceptions
        self.logger.error(f"Error during position update iteration: {e}")
```

### position_manager.py - Multiple Locations

```python
# BEFORE
ticker = self.client.get_ticker(symbol)

# AFTER
try:
    ticker = self.client.get_ticker(symbol)
except Exception as e:
    self.logger.warning(f"API error getting ticker: {type(e).__name__}: {e}")
    continue
```

---

## Testing Results

‚úÖ test_position_update_errors.py - 3/3 demonstrations pass  
‚úÖ test_fix_validation.py - 2/2 verifications pass  
‚úÖ test_bot_fixes.py - 4/4 existing tests pass  

---

## What This Fixes

### Before
‚ùå Generator exceptions break ALL position updates  
‚ùå Hard to debug which API call failed  
‚ùå Fallback logic can fail with NameError  

### After
‚úÖ Generator exceptions caught and logged  
‚úÖ Rich error context (exception types, API calls)  
‚úÖ Robust fallback with safety checks  

---

## Performance Impact

- **Lock overhead**: None (no new locks)
- **Exception handling overhead**: Negligible (~microseconds)
- **Memory impact**: None
- **Overall**: ZERO performance regression

---

## Deployment Notes

1. Changes are backward compatible
2. No config changes required
3. No database migrations needed
4. Monitor logs for generator exception patterns
5. Watch for any new error types in first 24 hours

---

## Quick Verification

```bash
# Run error handling tests
python3 test_position_update_errors.py

# Verify fixes are in place
python3 test_fix_validation.py

# Verify no regressions
python3 test_bot_fixes.py
```

All should pass ‚úÖ

---

## Files Modified

- `bot.py` - update_open_positions() method (1 critical fix)
- `position_manager.py` - update_positions() method (6 improvements)

## Files Added

- `test_position_update_errors.py` - Demonstrates the issues
- `test_fix_validation.py` - Verifies fixes are in place
- `POSITION_HANDLING_BUG_FIXES.md` - Full documentation
- `POSITION_HANDLING_QUICKREF.md` - This file
