"""
Test suite for position update error handling

Tests error scenarios in live position monitoring:
1. Generator exceptions during position updates
2. API timeout scenarios
3. Partial position update failures
"""
import sys
from datetime import datetime
import time


def test_generator_exception_handling():
    """
    Test that demonstrates the issue: generator exceptions are NOT caught
    by the inner try/except in update_open_positions()
    """
    print("\n" + "=" * 70)
    print("TEST: Generator Exception During Iteration")
    print("=" * 70)
    
    # Simulate the current implementation of update_open_positions
    class MockPosition:
        def __init__(self):
            self.entry_time = datetime.now()
            self.leverage = 10
            self.side = 'long'
            self.entry_price = 50000
    
    def failing_generator():
        """Generator that yields one item then raises"""
        yield "BTC-USDT", 0.05, MockPosition()
        # Simulate API error during iteration
        raise Exception("Simulated API error fetching next position")
    
    # Current implementation (BEFORE FIX)
    def current_update_open_positions():
        """Current implementation - inner try/except only"""
        for symbol, pnl, position in failing_generator():
            try:
                # Record analytics
                print(f"   Processing {symbol} with P/L: {pnl}")
            except Exception as e:
                print(f"   Error recording {symbol}: {e}")
        print("   Completed all position updates")
    
    # Test current implementation
    print("\n1. Testing CURRENT implementation (no outer try/except):")
    try:
        current_update_open_positions()
        print("   ✗ UNEXPECTED: Should have raised exception")
        return False
    except Exception as e:
        print(f"   ✓ Generator exception NOT caught: {type(e).__name__}")
        print(f"     Message: {str(e)}")
        print("   ⚠️  ISSUE CONFIRMED: Generator exceptions break the entire update")
        print()
    
    # Proposed fix implementation
    def fixed_update_open_positions():
        """Fixed implementation - outer try/except around generator"""
        try:
            for symbol, pnl, position in failing_generator():
                try:
                    # Record analytics
                    print(f"   Processing {symbol} with P/L: {pnl}")
                except Exception as e:
                    print(f"   Error recording {symbol}: {e}")
            print("   Completed all position updates")
        except Exception as e:
            print(f"   ⚠️  Generator error: {e}")
            print("   Continuing operation despite error...")
    
    # Test fixed implementation
    print("2. Testing FIXED implementation (outer try/except):")
    try:
        fixed_update_open_positions()
        print("   ✓ Generator exception caught and handled")
        print("   ✓ Operation continued despite error")
        return True
    except Exception as e:
        print(f"   ✗ UNEXPECTED: Fixed version should not raise: {e}")
        return False


def test_partial_position_update():
    """Test that partial updates work correctly with both implementations"""
    print("\n" + "=" * 70)
    print("TEST: Partial Position Update Success")
    print("=" * 70)
    
    class MockPosition:
        def __init__(self, symbol):
            self.symbol = symbol
            self.entry_time = datetime.now()
            self.leverage = 10
            self.side = 'long'
            self.entry_price = 50000
    
    def partial_generator():
        """Generator that yields items then fails"""
        yield "BTC-USDT", 0.05, MockPosition("BTC-USDT")
        yield "ETH-USDT", 0.03, MockPosition("ETH-USDT")
        raise Exception("API error on third position")
    
    # Track what was processed
    processed = []
    
    # Current implementation (BEFORE FIX)
    print("\n1. Current implementation:")
    processed.clear()
    try:
        for symbol, pnl, position in partial_generator():
            try:
                processed.append(symbol)
                print(f"   Processed {symbol}")
            except Exception as e:
                print(f"   Error: {e}")
    except Exception as e:
        print(f"   ⚠️  Generator crashed after processing {len(processed)} positions")
        print(f"      Positions processed: {processed}")
        print(f"      Error: {e}")
    
    # Fixed implementation
    print("\n2. Fixed implementation:")
    processed.clear()
    try:
        try:
            for symbol, pnl, position in partial_generator():
                try:
                    processed.append(symbol)
                    print(f"   Processed {symbol}")
                except Exception as e:
                    print(f"   Error: {e}")
        except Exception as e:
            print(f"   ⚠️  Generator error after processing {len(processed)} positions: {e}")
            print(f"      Positions processed: {processed}")
            print("   ✓ Error handled, operation continues")
    except Exception as e:
        print(f"   ✗ Unexpected outer exception: {e}")
    
    return len(processed) == 2


def test_error_logging_context():
    """Test that error logging provides sufficient context"""
    print("\n" + "=" * 70)
    print("TEST: Error Logging Context")
    print("=" * 70)
    
    class MockPosition:
        def __init__(self):
            self.entry_time = datetime.now()
            self.leverage = 10
            self.side = 'long'
            self.entry_price = 50000
    
    def generator_with_multiple_positions():
        yield "BTC-USDT", 0.05, MockPosition()
        yield "ETH-USDT", 0.03, MockPosition()
        raise Exception("API timeout - connection lost")
    
    # Test error logging
    print("\n1. Testing error context:")
    positions_processed = 0
    try:
        try:
            for symbol, pnl, position in generator_with_multiple_positions():
                try:
                    positions_processed += 1
                    print(f"   ✓ Processed position {positions_processed}: {symbol}")
                except Exception as e:
                    print(f"   ✗ Error processing position {symbol}: {e}")
        except Exception as e:
            print(f"\n   ⚠️  Generator failed after {positions_processed} successful updates")
            print(f"      Error type: {type(e).__name__}")
            print(f"      Error message: {str(e)}")
            print("   ✓ Sufficient context for debugging")
    except Exception as e:
        print(f"   ✗ Unexpected error: {e}")
    
    return positions_processed == 2


def main():
    """Run all tests and return exit code"""
    print("\n" + "=" * 70)
    print("POSITION UPDATE ERROR HANDLING TESTS")
    print("=" * 70)
    print("Demonstrating error scenarios in live position monitoring\n")
    
    results = []
    
    # Run tests
    results.append(("Generator Exception Handling", test_generator_exception_handling()))
    results.append(("Partial Position Update", test_partial_position_update()))
    results.append(("Error Logging Context", test_error_logging_context()))
    
    print("\n" + "=" * 70)
    print("TEST RESULTS SUMMARY")
    print("=" * 70)
    
    for name, passed in results:
        status = "✓ PASS" if passed else "✗ FAIL"
        print(f"{status}: {name}")
    
    all_passed = all(result[1] for result in results)
    
    if all_passed:
        print("\n✓ All demonstrations completed successfully")
        print("\nIMPORTANT: Tests show that generator exceptions ARE NOT caught")
        print("           by the current implementation. This needs to be fixed.")
        return 0
    else:
        print("\n✗ Some demonstrations failed")
        return 1


if __name__ == "__main__":
    exit(main())
